Workbook

Sheet Riepilogo
A1: Pagina | B1: Totale pagina (€)
A2: Pagina 1 | B2: ='Pag1'!J132
A3: Pagina 2 | B3: ='Pag2'!J130
A4: Pagina 3 | B4: ='Pag3'!J131
A5: Pagina 4 | B5: ='Pag4'!J131
A6: Pagina 5 | B6: ='Pag5'!J78
A8: TOTALE LISTINO | B8: =SUM(B2:B6)

Sheet Pag1
A1: CODE | B1: Line | C1: Name of the product | D1: Volume | E1: Standard package | F1: QTY | G1: Pieces per pallet | H1: PRICE | I1: BARCODE | J1: TOTAL (€)
A4: 120009848 | B4: LK OPC | C4: LK OPC 1/0 Nero | D4: 100 ML | E4: 72 | G4: 2160 | H4: 2.99 | I4: 1200098480015 | J4: =IF(F4="","",F4*H4)
A5: 120009452 | B5: LK OPC | C5: LK OPC 2/0 Bruno | D5: 100 ML | E5: 72 | G5: 2160 | H5: 2.99 | I5: 1200094520012 | J5: =IF(F5="","",F5*H5)
A6: 120009453 | B6: LK OPC | C6: LK OPC 3/0 Castano scuro | D6: 100 ML | E6: 72 | G6: 2160 | H6: 2.99 | I6: 1200094520012 | J6: =IF(F6="","",F6*H6)
A7: 120009454 | B7: LK OPC | C7: LK OPC 4/0 Castano | D7: 100 ML | E7: 72 | G7: 2160 | H7: 2.99 | I7: 1200094520012 | J7: =IF(F7="","",F7*H7)
A8: 120009455 | B8: LK OPC | C8: LK OPC 5/0 Castano chiaro | D8: 100 ML | E8: 72 | G8: 2160 | H8: 2.99 | I8: 1200094520012 | J8: =IF(F8="","",F8*H8)
A9: 120009456 | B9: LK OPC | C9: LK OPC 6/0 Biondo scuro | D9: 100 ML | E9: 72 | G9: 2160 | H9: 2.99 | I9: 1200094520012 | J9: =IF(F9="","",F9*H9)
A10: 120009457 | B10: LK OPC | C10: LK OPC 7/0 Biondo | D10: 100 ML | E10: 72 | G10: 2160 | H10: 2.99 | I10: 1200094520012 | J10: =IF(F10="","",F10*H10)
A11: 120009458 | B11: LK OPC | C11: LK OPC 8/0 Biondo chiaro | D11: 100 ML | E11: 72 | G11: 2160 | H11: 2.99 | I11: 1200094520012 | J11: =IF(F11="","",F11*H11)
A12: 120009459 | B12: LK OPC | C12: LK OPC 9/0 Biondo chiarissimo | D12: 100 ML | E12: 72 | G12: 2160 | H12: 2.99 | I12: 1200094520012 | J12: =IF(F12="","",F12*H12)
A13: 120009460 | B13: LK OPC | C13: LK OPC 10/0 Biondo chiarissimo plus | D13: 100 ML | E13: 72 | G13: 2160 | H13: 2.99 | I13: 1200094520012 | J13: =IF(F13="","",F13*H13)
A14: 120009461 | B14: LK OPC | C14: LK OPC 44/00 Castano profondo | D14: 100 ML | E14: 72 | G14: 2160 | H14: 2.99 | I14: 1200094520012 | J14: =IF(F14="","",F14*H14)
A15: 120009462 | B15: LK OPC | C15: LK OPC 55/00 Castano chiaro profondo | D15: 100 ML | E15: 72 | G15: 2160 | H15: 2.99 | I15: 1200094520012 | J15: =IF(F15="","",F15*H15)
... A27: 120009480 | B27: LK OPC | C27: LK OPC 1/01 Nero blu | D27: 100 ML | E27: 72 | G27: 2160 | H27: 2.99 | I27: 1200094520012 | J27: =IF(F27="","",F27*H27)
A28: 120009488 | B28: LK OPC | C28: LK OPC 4/28 Castano cenere perla | D28: 100 ML | E28: 72 | G28: 2160 | H28: 2.99 | J28: =IF(F28="","",F28*H28)
A29: 120009449 | B29: LK OPC | C29: LK OPC 5/28 Castano Chiaro Cenere Perla | D29: 100 ML | E29: 72 | G29: 2160 | H29: 2.99 | I29: 1200094490018 | J29: =IF(F29="","",F29*H29)
A30: 120009450 | B30: LK OPC | C30: LK OPC 6/28 Biondo Scuro Cenere Perla | D30: 100 ML | E30: 72 | G30: 2160 | H30: 2.99 | I30: 1200094500014 | J30: =IF(F30="","",F30*H30)
A31: 120009451 | B31: LK OPC | C31: LK OPC 7/28 Biondo Cenere Perla | D31: 100 ML | E31: 72 | G31: 2160 | H31: 2.99 | I31: 1200094510013 | J31: =IF(F31="","",F31*H31)
A32: 120009489 | B32: LK OPC | C32: LK OPC 8/28 Biondo chiaro cenere perla | D32: 100 ML | E32: 72 | G32: 2160 | H32: 2.99 | I32: 1200094510013 | J32: =IF(F32="","",F32*H32)
A33: 120009490 | B33: LK OPC | C33: LK OPC 9/28 Biondo chiarissimo cenre perla | D33: 100 ML | E33: 72 | G33: 2160 | H33: 2.99 | I33: 1200094510013 | J33: =IF(F33="","",F33*H33)
A34: 120009491 | B34: LK OPC | C34: LK OPC 10/28 Biondo Chiarissimo Cenere perla plus | D34: 100 ML | E34: 72 | G34: 2160 | H34: 2.99 | I34: 1200094510013 | J34: =IF(F34="","",F34*H34)
A35: 120009892 | B35: LK OPC | C35: LK OPC 4/9 Castano Cool Brown | D35: 100 ML | E35: 72 | G35: 2160 | H35: 2.99 | I35: 1200094510013 | J35: =IF(F35="","",F35*H35)
A36: 120009893 | B36: LK OPC | C36: LK OPC 5/9 Castano Chiaro Cool Brown | D36: 100 ML | E36: 72 | G36: 2160 | H36: 2.99 | I36: 1200094510013 | J36: =IF(F36="","",F36*H36)
A37: 120009894 | B37: LK OPC | C37: LK OPC 6/9 Biondo Scuro Cool Brown | D37: 100 ML | E37: 72 | G37: 2160 | H37: 2.99 | I37: 1200094510013 | J37: =IF(F37="","",F37*H37)
A38: 120009895 | B38: LK OPC | C38: LK OPC 7/9 Biondo Cool Brown | D38: 100 ML | E38: 72 | G38: 2160 | H38: 2.99 | I38: 1200094510013 | J38: =IF(F38="","",F38*H38)
A39: 120009887 | B39: LK OPC | C39: LK OPC 4/26 Catano Cenere Rame | D39: 100 ML | E39: 72 | G39: 2160 | H39: 2.99 | I39: 1200098870014 | J39: =IF(F39="","",F39*H39)
A40: 120009888 | B40: LK OPC | C40: LK OPC 5/26 Castano Chiaro Cenere Rame | D40: 100 ML | E40: 72 | G40: 2160 | H40: 2.99 | I40: 1200098870014 | J40: =IF(F40="","",F40*H40)
... A117: 120009905 | B117: LK OPC | C117: LK OPC 10/08 BIONDO CHIARISSIMO PLUS NATURALE IRISE' | D117: 100 ML | E117: 72 | G117: 2160 | H117: 2.99 | I117: 1200099000014 | J117: =IF(F117="","",F117*H117)
A118: 120009301 | B118: LK OPC | C118: LK OPC RED | D118: 100 ML | E118: 72 | G118: 2160 | H118: 2.99 | J118: =IF(F118="","",F118*H118)
A119: 120009302 | B119: LK OPC | C119: LK OPC YELLOW | D119: 100 ML | E119: 72 | G119: 2160 | H119: 2.99 | J119: =IF(F119="","",F119*H119)
A120: 120009303 | B120: LK OPC | C120: LK OPC GREEN | D120: 100 ML | E120: 72 | G120: 2160 | H120: 2.99 | J120: =IF(F120="","",F120*H120)
A121: 120009304 | B121: LK OPC | C121: LK OPC BLU | D121: 100 ML | E121: 72 | G121: 2160 | H121: 2.99 | J121: =IF(F121="","",F121*H121)
A122: 120009305 | B122: LK OPC | C122: LK OPC VIOLET | D122: 100 ML | E122: 72 | G122: 2160 | H122: 2.99 | J122: =IF(F122="","",F122*H122)
A123: 120009306 | B123: LK OPC | C123: LK OPC ORANGE | D123: 100 ML | E123: 72 | G123: 2160 | H123: 2.99 | J123: =IF(F123="","",F123*H123)
A125: 120035001 | B125: ESCALATION | C125: ESCALATION ® 1/00 NERO | D125: 100ML | E125: 72 | G125: 2160 | H125: 2.99 | I125: 1200350010011 | J125: =IF(F125="","",F125*H125)
A126: 120035002 | B126: ESCALATION | C126: ESCALATION ® 2/00 BRUNO | D126: 100ML | E126: 72 | G126: 2160 | H126: 2.99 | I126: 1200350010011 | J126: =IF(F126="","",F126*H126)
A127: 120035003 | B127: ESCALATION | C127: ESCALATION ® 3/00 CASTANO SCURO | D127: 100ML | E127: 72 | G127: 2160 | H127: 2.99 | I127: 1200350010011 | J127: =IF(F127="","",F127*H127)
A128: 120035004 | B128: ESCALATION | C128: ESCALATION ® 4/00 CASTANO NATURALE | D128: 100ML | E128: 72 | G128: 2160 | H128: 2.99 | I128: 1200350010011 | J128: =IF(F128="","",F128*H128)
A129: 120035005 | B129: ESCALATION | C129: ESCALATION ® 5/00 CASTANO CHIARO | D129: 100ML | E129: 72 | G129: 2160 | H129: 2.99 | I129: 1200350010011 | J129: =IF(F129="","",F129*H129)
A130: 120035006 | B130: ESCALATION | C130: ESCALATION ® 6/00 BIONDO SCURO | D130: 100ML | E130: 72 | G130: 2160 | H130: 2.99 | I130: 1200350010011 | J130: =IF(F130="","",F130*H130)
...

Sheet Pag2
A1: CODE | B1: Line | C1: Name of the product | D1: Volume | E1: Standard package | F1: QTY | G1: Pieces per pallet | H1: PRICE | I1: BARCODE | J1: TOTAL (€)
A2: 120035008 | B2: ESCALATION | C2: ESCALATION ® 8/00 BIONDO CHIARO | D2: 100ML | E2: 72 | G2: 2160 | H2: 2.99 | I2: 1200350010011 | J2: =IF(F2="","",F2*H2)
A3: 120035009 | B3: ESCALATION | C3: ESCALATION ® 9/00 BIONDO CHIARISSIMO | D3: 100ML | E3: 72 | G3: 2160 | H3: 2.99 | I3: 1200350010011 | J3: =IF(F3="","",F3*H3)
A4: 120035010 | B4: ESCALATION | C4: ESCALATION ® 10/00 BIONDO CHIARISSIMO ULTRA | D4: 100ML | E4: 72 | G4: 2160 | H4: 2.99 | I4: 1200350010011 | J4: =IF(F4="","",F4*H4)
A5: 120035011 | B5: ESCALATION | C5: ESCALATION ® 1/01 NERO BLU | D5: 100ML | E5: 72 | G5: 2160 | H5: 2.99 | I5: 1200350010011 | J5: =IF(F5="","",F5*H5)
A6: 120035012 | B6: ESCALATION | C6: ESCALATION ® 4/2 CASTANO CENERE | D6: 100ML | E6: 72 | G6: 2160 | H6: 2.99 | I6: 1200350010011 | J6: =IF(F6="","",F6*H6)
A7: 120035013 | B7: ESCALATION | C7: ESCALATION ® 5/2 CASTANO CHIARO CENERE | D7: 100ML | E7: 72 | G7: 2160 | H7: 2.99 | I7: 1200350010011 | J7: =IF(F7="","",F7*H7)
A8: 120035014 | B8: ESCALATION | C8: ESCALATION ® 6/2 BIONDO SCURO CENERE | D8: 100ML | E8: 72 | G8: 2160 | H8: 2.99 | I8: 1200350010011 | J8: =IF(F8="","",F8*H8)
A9: 120035015 | B9: ESCALATION | C9: ESCALATION ® 7/2 BIONDO CENERE | D9: 100ML | E9: 72 | G9: 2160 | H9: 2.99 | I9: 1200350010011 | J9: =IF(F9="","",F9*H9)
A10: 120035016 | B10: ESCALATION | C10: ESCALATION ® 8/2 BIONDO CHIARO CENERE | D10: 100ML | E10: 72 | G10: 2160 | H10: 2.99 | I10: 1200350010011 | J10: =IF(F10="","",F10*H10)
A11: 120035017 | B11: ESCALATION | C11: ESCALATION ® 9/2 BIONDO CHIARISSIMO CENERE | D11: 100ML | E11: 72 | G11: 2160 | H11: 2.99 | I11: 1200350010011 | J11: =IF(F11="","",F11*H11)
A12: 120035018 | B12: ESCALATION | C12: ESCALATION ® 10/2 BIONDO CHIARISSIMO ULTRA CENERE | D12: 100ML | E12: 72 | G12: 2160 | H12: 2.99 | I12: 1200350010011 | J12: =IF(F12="","",F12*H12)
A13: 120035019 | B13: ESCALATION | C13: ESCALATION ® 5/03 CASTANO CHIARO NATURALE DORATO | D13: 100ML | E13: 72 | G13: 2160 | H13: 2.99 | I13: 1200350010011 | J13: =IF(F13="","",F13*H13)
... A128: 120045625 | B128: FILTER DOUSCOLOR | C128: 6/55 BIONDO SCURO ROSSO VIBRANTE | D128: 60 ML | E128: 72 | G128: 3240 | H128: 2.99 | I128: 1200456250014 | J128: =IF(F128="","",F128*H128)
I130: Totale pagina | J130: =SUM(J2:J128)

Sheet Pag3
A1: CODE | B1: Line | C1: Name of the product | D1: Volume | E1: Standard package | F1: QTY | G1: Pieces per pallet | H1: PRICE | I1: BARCODE | J1: TOTAL (€)
A2: 120045620 | B2: FILTER DOUSCOLOR | C2: 7/2 BIONDO CENERE | D2: 60 ML | E2: 72 | G2: 3240 | H2: 2.99 | I2: 1200456200019 | J2: =IF(F2="","",F2*H2)
A3: 120045633 | B3: FILTER DOUSCOLOR | C3: 7/26 BIONDO CENERE RAME | D3: 60 ML | E3: 72 | G3: 3240 | H3: 2.99 | I3: 1200456330013 | J3: =IF(F3="","",F3*H3)
A4: 120045630 | B4: FILTER DOUSCOLOR | C4: 7/3 BIONDO DORATO | D4: 60 ML | E4: 72 | G4: 3240 | H4: 2.99 | I4: 1200456300016 | J4: =IF(F4="","",F4*H4)
A5: 120045642 | B5: FILTER DOUSCOLOR | C5: 7/82 BIONDO IRISE' CENERE | D5: 60 ML | E5: 72 | G5: 3240 | H5: 2.99 | I5: 1200456420011 | J5: =IF(F5="","",F5*H5)
A6: 120045640 | B6: FILTER DOUSCOLOR | C6: 8/28 BIONDO CHIARO CENERE PERLA | D6: 60 ML | E6: 72 | G6: 3240 | H6: 2.99 | I6: 1200456400013 | J6: =IF(F6="","",F6*H6)
A7: 120045647 | B7: FILTER DOUSCOLOR | C7: 8/7 BIONDO CHIARO BEIGE | D7: 60 ML | E7: 72 | G7: 3240 | H7: 2.99 | I7: 1200456470016 | J7: =IF(F7="","",F7*H7)
A8: 120045636 | B8: FILTER DOUSCOLOR | C8: 8/78 BIONDO CHIARO MOKA | D8: 60 ML | E8: 72 | G8: 3240 | H8: 2.99 | I8: 1200456360010 | J8: =IF(F8="","",F8*H8)
A9: 120045643 | B9: FILTER DOUSCOLOR | C9: 8/82 BIONDO CHIARO IRISE' CENERE | D9: 60 ML | E9: 72 | G9: 3240 | H9: 2.99 | I9: 1200456430010 | J9: =IF(F9="","",F9*H9)
A10: 120045621 | B10: FILTER DOUSCOLOR | C10: 9/2 BIONDO CHIARISSIMO CENERE | D10: 60 ML | E10: 72 | G10: 3240 | H10: 2.99 | I10: 1200456210018 | J10: =IF(F10="","",F10*H10)
A11: 120045631 | B11: FILTER DOUSCOLOR | C11: 9/3 BIONDO CHIARISSIMO DORATO | D11: 60 ML | E11: 72 | G11: 3240 | H11: 2.99 | I11: 1200456310015 | J11: =IF(F11="","",F11*H11)
A12: 120045628 | B12: FILTER DOUSCOLOR | C12: 9/4 BIONDO CHIARISSIMO MOGANO | D12: 60 ML | E12: 72 | G12: 3240 | H12: 2.99 | I12: 1200456280011 | J12: =IF(F12="","",F12*H12)
A13: 120045648 | B13: FILTER DOUSCOLOR | C13: 9/7 BIONDO CHIARISSIMO BEIGE | D13: 60 ML | E13: 72 | G13: 3240 | H13: 2.99 | I13: 1200456480015 | J13: =IF(F13="","",F13*H13)
... A16: 120045650 | B16: FILTER DOUSCOLOR | C16: EXTRA SHINE | D16: 60 ML | E16: 72 | G16: 3240 | H16: 2.99 | I16: 1200456500010 | J16: =IF(F16="","",F16*H16)
A19: 120626011 | B19: Absolute | C19: 3/00 | D19: 60 ML | E19: 72 | G19: 3240 | I19: None | J19: =IF(F19="","",F19*H19)
A20: 120626012 | B20: Absolute | C20: 4/00 | D20: 60 ML | E20: 72 | G20: 3240 | I20: None | J20: =IF(F20="","",F20*H20)
A21: 120626010 | B21: Absolute | C21: 5/00 | D21: 60 ML | E21: 72 | G21: 3240 | I21: 1206260100019 | J21: =IF(F21="","",F21*H21)
A22: 120626013 | B22: Absolute | C22: 6/00 | D22: 60 ML | E22: 72 | G22: 3240 | I22: 1206260100019 | J22: =IF(F22="","",F22*H22)
A23: 120626014 | B23: Absolute | C23: 7/00 | D23: 60 ML | E23: 72 | G23: 3240 | I23: 1206260100019 | J23: =IF(F23="","",F23*H23)
A24: 120626015 | B24: Absolute | C24: 8/00 | D24: 60 ML | E24: 72 | G24: 3888 | I24: 1206260100019 | J24: =IF(F24="","",F24*H24)
A25: 120626016 | B25: Absolute | C25: 9/00 | D25: 60 ML | E25: 72 | G25: 3240 | I25: 1206260100019 | J25: =IF(F25="","",F25*H25)
A26: 120626017 | B26: Absolute | C26: 10/00 | D26: 60 ML | E26: 72 | G26: 3240 | I26: 1206260100019 | J26: =IF(F26="","",F26*H26)
A28: 120626018 | B28: Absolute | C28: 4/03 | D28: 60 ML | E28: 72 | G28: 3240 | I28: 1206260100019 | J28: =IF(F28="","",F28*H28)
A29: 120626019 | B29: Absolute | C29: 5/03 | D29: 60 ML | E29: 72 | G29: 3240 | I29: 1206260100019 | J29: =IF(F29="","",F29*H29)
A30: 120626020 | B30: Absolute | C30: 6/03 | D30: 60 ML | E30: 72 | G30: 3240 | I30: 1206260100019 | J30: =IF(F30="","",F30*H30)
A31: 120626021 | B31: Absolute | C31: 7/03 | D31: 60 ML | E31: 72 | G31: 3240 | I31: 1206260100019 | J31: =IF(F31="","",F31*H31)
... A109: 120626091 | B109: Absolute | C109: 5/08 | D109: 60 ML | E109: 72 | G109: 3240 | I109: 1206260100019 | J109: =IF(F109="","",F109*H109)
A111: 240026000 | B111: DEVELOPER | C111: 5 VOLUMI 1000ML | D111: 1000ML | G111: 576 | H111: 2.69 | J111: =IF(F111="","",F111*H111)
A112: 240027000 | B112: DEVELOPER | C112: 10 VOLUMI 1000ML | D112: 1000ML | G112: 576 | H112: 2.69 | J112: =IF(F112="","",F112*H112)
A113: 240028000 | B113: DEVELOPER | C113: 20 VOLUMI 1000ML | D113: 1000ML | G113: 576 | H113: 2.69 | J113: =IF(F113="","",F113*H113)
A114: 240029000 | B114: DEVELOPER | C114: 30 VOLUMI 1000ML | D114: 1000ML | G114: 576 | H114: 2.69 | J114: =IF(F114="","",F114*H114)
A115: 240030000 | B115: DEVELOPER | C115: 40 VOLUMI 1000ML | D115: 1000ML | G115: 576 | H115: 2.69 | J115: =IF(F115="","",F115*H115)
A117: 150025000 | B117: BLEACHER | C117: Decolorante Light Scale 9 | D117: 500gr | E117: 2 | G117: 490 | H117: 9.15 | I117: 1500250000014 | J117: =IF(F117="","",F117*H117)
A118: 150029000 | B118: BLEACHER | C118: Decolorante Light Scale 10 NEW! | D118: 500gr | E118: 1 | G118: 840 | H118: 12.53 | I118: 1500290000012 | J118: =IF(F118="","",F118*H118)
A119: 150036000 | B119: BLEACHER | C119: LIGHT SCALE CLAY DECOLORANTE ARGILLA GRIGIA NEW! | D119: 400gr | E119: 1 | G119: 720 | H119: 9.37 | I119: 1500360000010 | J119: =IF(F119="","",F119*H119)
A120: 150037000 | B120: BLEACHER | C120: LIGHT SCALE PLATINUM DECOLORANTE POLVERE GRIGIA NEW! | D120: 500gr | E120: 6 | G120: 720 | H120: 11.7 | I120: 1500370000017 | J120: =IF(F120="","",F120*H120)
A121: 150031000 | B121: BLEACHER | C121: Bleach & Lights PRO TECH | D121: 1000GR | E121: 6 | G121: 168 | H121: 11.99 | J121: =IF(F121="","",F121*H121)
A122: 150030000 | B122: BLEACHER | C122: Light Scale Color Remover NEW! | D122: 12×25 GR | E122: 288 | G122: 8640 | H122: 1.21 | I122: 1500300000018 | J122: =IF(F122="","",F122*H122)
A123: 150044000 | B123: Light Scale | C123: LIGHT SCALE LIGHTENING OIL 500 | D123: 500ml | E123: 6 | H123: 8.25 | J123: =IF(F123="","",F123*H123)
A125: 120034001 | B125: Light Scale | C125: Light Scale Color 03 Sun Light | D125: 100 ml | E125: 72 | G125: 2160 | H125: 2.99 | I125: 1200340010014 | J125: =IF(F125="","",F125*H125)
...

Sheet Pag4
A1: CODE | B1: Line | C1: Name of the product | D1: Volume | E1: Standard package | F1: QTY | G1: Pieces per pallet | H1: PRICE | I1: BARCODE | J1: TOTAL (€)
A2: 120034007 | B2: Light Scale | C2: Light Scale Color Light Pearl | D2: 100 ml | E2: 72 | G2: 2160 | H2: 2.99 | I2: 1200340010014 | J2: =IF(F2="","",F2*H2)
A3: 120034008 | B3: Light Scale | C3: Light Scale Color Lilla Flower | D3: 100 ml | E3: 72 | G3: 2160 | H3: 2.99 | I3: 1200340010014 | J3: =IF(F3="","",F3*H3)
A4: 120034009 | B4: Light Scale | C4: Light Scale Color Orange Pink | D4: 100 ml | E4: 72 | G4: 2160 | H4: 2.99 | I4: 1200340010014 | J4: =IF(F4="","",F4*H4)
A6: 110094000 | B6: Light Scale Care | C6: Light Scale Anti Yellow Shampoo | D6: 250 ml | E6: 6 | G6: 1080 | H6: 3.15 | I6: 1100940000012 | J6: =IF(F6="","",F6*H6)
A7: 110093000 | B7: Light Scale Care | C7: Light Scale Anti Yellow Shampoo | D7: 1000 ml | E7: 4 | G7: 288 | H7: 6.41 | I7: 1100930000015 | J7: =IF(F7="","",F7*H7)
A8: 110096000 | B8: Light Scale Care | C8: Light Scale Anti Yellow Mask | D8: 500 ml | E8: 2 | G8: 490 | H8: 5.72 | I8: 1100960000016 | J8: =IF(F8="","",F8*H8)
A9: 110095000 | B9: Light Scale Care | C9: Light Scale Anti Yellow Mask | D9: 1000 ml | E9: 4 | G9: 420 | H9: 8.74 | I9: 1100950000019 | J9: =IF(F9="","",F9*H9)
A10: 130003000 | B10: Light Scale Care | C10: Light Scale Anti Yellow Spray | D10: 125 ml | E10: 6 | G10: 2052 | H10: 6.44 | I10: 1300030000018 | J10: =IF(F10="","",F10*H10)
A11: 130004000 | B11: Light Scale Care | C11: Light Scale Anti Yellow Mousse | D11: 250 ml | E11: 6 | G11: 1080 | H11: 6.45 | I11: 1300030000018 | J11: =IF(F11="","",F11*H11)
A12: 190182000 | B12: Light Scale Care | C12: Light Scale Anti Yellow Kit (6 Shampoo 100 ml + 6 Mask 100 ml) | D12: 12x100 ml | E12: 1 | G12: 136 | H12: 28.95 | I12: 1901820000012 | J12: =IF(F12="","",F12*H12)
A14: 160011000 | B14: KC Natural Waves | C14: Keep Control - Clarifying Shampoo | D14: 500 ml | E14: 1 | G14: 1080 | H14: 5.15 | I14: 1600110000014 | J14: =IF(F14="","",F14*H14)
A15: 160015000 | B15: KC Natural Waves | C15: Keep Control - Equalizer | D15: 250 ml | E15: 1 | G15: 1680 | H15: 4.44 | I15: 1600150000012 | J15: =IF(F15="","",F15*H15)
... A22: 170013000 | B22: Fashion | C22: «Lisap Fashion Straightener» | D22: 200 ml | E22: 6 | G22: 1800 | H22: 3.92 | I22: 1700130000015 | J22: =IF(F22="","",F22*H22)
A23: 170014000 | B23: Fashion | C23: «Lisap Fashion Gloss Shine» | D23: 250 ml | E23: 6 | G23: 1800 | I23: None | J23: =IF(F23="","",F23*H23)
A24: 170061000 | B24: Fashion | C24: VOLUME UP | D24: 6 GR | E24: 12 | H24: 4.49 | J24: =IF(F24="","",F24*H24)
A25: 170015000 | B25: Fashion | C25: «Lisap Fashion Styling Spray» | D25: 250 ml | E25: 6 | G25: 1080 | H25: 4.15 | I25: 1700150000019 | J25: =IF(F25="","",F25*H25)
A26: 170948000 | B26: Fashion Extreme | C26: «Lisap Fashion Mousse Design Regular» | D26: 250 ml | E26: 6 | G26: 984 | H26: 2.62 | I26: 1709480000010 | J26: =IF(F26="","",F26*H26)
A28: 170027000 | B28: Fashion Extreme | C28: «Lisap Fashion Extreme Gel Mousse» | D28: 250 ml | E28: 6 | G28: 984 | H28: 3.77 | I28: 1700270000012 | J28: =IF(F28="","",F28*H28)
A29: 170028000 | B29: Fashion Extreme | C29: «Lisap Fashion Extreme Eco-Spray» | D29: 250 ml | E29: 6 | G29: 984 | H29: 3.99 | I29: 1700280000019 | J29: =IF(F29="","",F29*H29)
A30: 170949000 | B30: Fashion Extreme | C30: «Lisap Fashion Mousse Design Strong» | D30: 250 ml | E30: 6 | G30: 984 | H30: 3.27 | I30: 1709490000017 | J30: =IF(F30="","",F30*H30)
A32: 140400000 | B32: High Tech | C32: «High Tech Hair Spray Natural Hold» | D32: 500 ml | E32: 12 | G32: 684 | H32: 2.65 | I32: 1404000000012 | J32: =IF(F32="","",F32*H32)
A33: 140401000 | B33: High Tech | C33: «High Tech Hair Spray Strong Hold» | D33: 500 ml | E33: 12 | G33: 684 | H33: 2.73 | I33: 1404010000019 | J33: =IF(F33="","",F33*H33)
A34: 140402000 | B34: High Tech | C34: «High Tech Hair No Gas Natural» | D34: 300 ml | E34: 12 | G34: 1056 | H34: 2.98 | I34: 1404020000016 | J34: =IF(F34="","",F34*H34)
A35: 140403000 | B35: High Tech | C35: «High Tech Hair No Gas Strong» | D35: 300 ml | E35: 12 | G35: 1056 | H35: 2.98 | I35: 1404030000013 | J35: =IF(F35="","",F35*H35)
A36: 170874000 | B36: High Tech | C36: «High Tech Hair Mousse Volumizing Strong» | D36: 300 ml | E36: 12 | G36: 1008 | H36: 2.54 | I36: 1708740000012 | J36: =IF(F36="","",F36*H36)
A37: 170875000 | B37: High Tech | C37: «High Tech Hair Mousse Brushing» | D37: 300 ml | E37: 12 | G37: 1008 | H37: 2.54 | I37: 1708750000019 | J37: =IF(F37="","",F37*H37)
A38: 170876000 | B38: High Tech | C38: «High Tech Hair Gel Mousse Wet Effect» | D38: 300 ml | E38: 12 | G38: 1008 | H38: 2.84 | I38: 1708760000016 | J38: =IF(F38="","",F38*H38)
... A47: 170962000 | B47: Sculture | C47: "Sleek Spray" | D47: 200 ml | E47: 6 | G47: 1080 | H47: 2.99 | I47: 1709620000016 | J47: =IF(F47="","",F47*H47)
A48: 170967000 | B48: Sculture | C48: "Gum" | D48: 150 ml | E48: 4 | G48: 1840 | I48: None | J48: =IF(F48="","",F48*H48)
A49: 170964000 | B49: Sculture | C49: "Shining Gel Mousse" | D49: 300 ml | E49: 12 | G49: 1008 | H49: 2.91 | I49: 1709640000010 | J49: =IF(F49="","",F49*H49)
A50: 170963000 | B50: Sculture | C50: "Strong Mousse" | D50: 300 ml | E50: 12 | G50: 1008 | H50: 2.86 | I50: 1709630000013 | J50: =IF(F50="","",F50*H50)
A51: 170965000 | B51: Sculture | C51: "Eco Spray" | D51: 250 ml | E51: 12 | G51: 1056 | H51: 3.14 | I51: 1709650000017 | J51: =IF(F51="","",F51*H51)
A52: 170966000 | B52: Sculture | C52: "Extrastrong Spray Gel" | D52: 250 ml | E52: 6 | G52: 1080 | H52: 3.48 | I52: 1709660000014 | J52: =IF(F52="","",F52*H52)
A53: 170961000 | B53: Sculture | C53: "Extrastrong Gel" | D53: 150 ml | E53: 6 | G53: 2040 | H53: 2.78 | I53: 1709610000019 | J53: =IF(F53="","",F53*H53)
A54: 170065000 | B54: Sculture | C54: "Creator Water Wax" | D54: 75 ml | E54: 4 | G54: 4032 | H54: 5.67 | I54: 1709680000018 | J54: =IF(F54="","",F54*H54)
A55: 170059000 | B55: Sculture | C55: Desing Jelly Gel | D55: 150 ml | E55: 4 | G55: 1440 | H55: 3.91 | I55: 1700590000013 | J55: =IF(F55="","",F55*H55)
A57: 110186000 | B57: Daily | C57: T.C.R Daily Care Shampoo 5000 ml cf. 2 pz. | D57: 5000 ml | E57: 2 | G57: 96 | H57: 7.28 | I57: 1100920000018 | J57: =IF(F57="","",F57*H57)
A59: 110168000 | B59: sunset ritual | C59: After Sun Shampoo & Shower Gel | D59: 250ml | E59: 6 | H59: 3.34 | I59: 1101680000010 | J59: =IF(F59="","",F59*H59)
A60: 180081000 | B60: sunset ritual | C60: After Sun Repairing Mask-Export | D60: 200ml | E60: 6 | H60: 4.03 | I60: 1800870000013 | J60: =IF(F60="","",F60*H60)
...

Sheet Pag5
A1: CODE | B1: Line | C1: Name of the product | D1: Volume | E1: Standard package | F1: QTY | G1: Pieces per pallet | H1: PRICE | I1: BARCODE | J1: TOTAL (€)
A2: 120014005 | B2: LISAPLEX XTREME | C2: LISAPLEX XTREME COLOR MYSTIC BLUE | D2: 60 ml | E2: 3 | G2: 3888 | H2: 2.99 | I2: 1200140010016 | J2: =IF(F2="","",F2*H2)
A3: 120014006 | B3: LISAPLEX XTREME | C3: LISAPLEX XTREME COLOR MOODY PURPLE | D3: 60 ml | E3: 3 | G3: 3888 | H3: 2.99 | I3: 1200140010016 | J3: =IF(F3="","",F3*H3)
A4: 120014007 | B4: LISAPLEX XTREME | C4: LISAPLEX XTREME COLOR NAUGHTY ORANGE | D4: 60 ml | E4: 3 | G4: 3888 | H4: 2.99 | I4: 1200140010016 | J4: =IF(F4="","",F4*H4)
A5: 120014008 | B5: LISAPLEX XTREME | C5: LISAPLEX XTREME COLOR PURE DIAMOND | D5: 60 ml | E5: 3 | G5: 3888 | H5: 2.99 | I5: 1200140010016 | J5: =IF(F5="","",F5*H5)
A8: 110045000 | B8: Keraplant Nature | C8: Keraplant Nature Shampoo Dermo-Calmante 250 ml. (cf. 4 pz) | D8: 250 ml | E8: 4 | G8: 1080 | H8: 4.15 | I8: 1100450000014 | J8: =IF(F8="","",F8*H8)
A9: 110046000 | B9: Keraplant Nature | C9: Keraplant Nature Shampoo Dermo-Calmante 1000 ml. (cf 4 pz) | D9: 1000 ml | E9: 4 | G9: 288 | H9: 8.8 | I9: 1100460000011 | J9: =IF(F9="","",F9*H9)
A10: 220004000 | B10: Keraplant Nature | C10: Keraplant Nature Fango Dermo-Calmante 250 ml (Cf.4 pz) | D10: 250 ml | E10: 4 | G10: 864 | H10: 11.21 | I10: 2200040000017 | J10: =IF(F10="","",F10*H10)
A11: 220027000 | B11: Keraplant Nature | C11: Keraplant Nature Olio Essenziale Dermo-Calmante 30 ml (cf 6 pz) | D11: 30 ml | E11: 6 | G11: 1971 | H11: 7.48 | I11: 2200270000016 | J11: =IF(F11="","",F11*H11)
A12: 220006000 | B12: Keraplant Nature | C12: Keraplant Nature Lozione Dermocalmante 150 ml (cf. 6 pz) | D12: 150 ml | E12: 6 | G12: 1080 | H12: 4.8 | I12: 2200060000011 | J12: =IF(F12="","",F12*H12)
A14: 220014000 | B14: Keraplant Nature | C14: Keraplant Nature Mud Detossinante 250 ml (4 pz) | D14: 250 ml | E14: 4 | G14: 864 | H14: 10.98 | I14: 2200140000016 | J14: =IF(F14="","",F14*H14)
A16: 110060000 | B16: Keraplant Nature | C16: Keraplant Nature Shampoo Seboregolatore 250 ml (cf. 4 pz) | D16: 250 ml | E16: 4 | G16: 1296 | H16: 4.15 | I16: 1100600000017 | J16: =IF(F16="","",F16*H16)
A17: 110061000 | B17: Keraplant Nature | C17: Keraplant Nature Shampoo Seboregolatore 1000 ml (cf. 4 pz) | D17: 1000 ml | E17: 4 | G17: 2016 | H17: 8.8 | I17: 1100610000014 | J17: =IF(F17="","",F17*H17)
... A21: 110054000 | B21: Keraplant Nature | C21: Keraplant Nature Shampoo Energizante 1000 ml (cf 4 pz) | D21: 1000 ml | E21: 4 | G21: 288 | H21: 8.8 | I21: 1100540000016 | J21: =IF(F21="","",F21*H21)
A22: 220012000 | B22: Keraplant Nature | C22: Keraplant Nature trattamento energizzante 6x8 ml | D22: 8ml | H22: 4.72 | J22: =IF(F22="","",F22*H22)
A23: 220025000 | B23: Keraplant Nature | C23: Keraplant Nature Trattamento Energizante Intensivo 100 ml (cf 4 pz) | D23: 100 ml | E23: 4 | G23: 1892 | H23: 14.25 | I23: 2200250000012 | J23: =IF(F23="","",F23*H23)
A25: 110057000 | B25: Keraplant Nature | C25: Keraplant Nature Shampoo Purificante 250 ml (cf. 4 pz) | D25: 250 ml | E25: 4 | G25: 1296 | H25: 4.15 | I25: 1100570000017 | J25: =IF(F25="","",F25*H25)
A26: 110089000 | B26: Keraplant Nature | C26: Keraplant Nature Shampoo Purificante 1000 ml (cf. 4 pz) | D26: 1000 ml | E26: 4 | G26: 384 | H26: 8.8 | I26: 1100890000018 | J26: =IF(F26="","",F26*H26)
A27: 110088000 | B27: Keraplant Nature | C27: Keraplant Nature Peeling Purificante 50 ml (cf. 4 pz x 4 tubi) | D27: 50 ml | G27: 2256 | H27: 4.49 | I27: 1100880000042 | J27: =IF(F27="","",F27*H27)
A28: 220020000 | B28: Keraplant Nature | C28: Keraplant Nature Lozione Purificante 150 ml (cf 6 pz) | D28: 150 ml | E28: 6 | G28: 1404 | H28: 4.8 | I28: 2200200000017 | J28: =IF(F28="","",F28*H28)
A30: 130005001 | B30: Refresh | C30: SILVER | D30: 250 ml | E30: 6 | G30: 1200 | H30: 4.89 | I30: 1300050010011 | J30: =IF(F30="","",F30*H30)
A31: 130005002 | B31: Refresh | C31: ANTHRACITE | D31: 250 ml | E31: 6 | G31: 1200 | H31: 4.89 | I31: 1300050010011 | J31: =IF(F31="","",F31*H31)
A32: 130005003 | B32: Refresh | C32: CHOCOLATE | D32: 250 ml | E32: 6 | G32: 7200 | H32: 4.89 | I32: 1300050010011 | J32: =IF(F32="","",F32*H32)
A33: 130005004 | B33: Refresh | C33: BRONZE | D33: 250 ml | E33: 6 | G33: 1200 | H33: 4.89 | I33: 1300050010011 | J33: =IF(F33="","",F33*H33)
A34: 130005005 | B34: Refresh | C34: GOLDEN | D34: 250 ml | E34: 6 | G34: 1200 | H34: 4.89 | I34: 1300050010011 | J34: =IF(F34="","",F34*H34)
A35: 130005006 | B35: Refresh | C35: COPPER | D35: 250 ml | E35: 6 | G35: 1200 | H35: 4.89 | I35: 1300050010011 | J35: =IF(F35="","",F35*H35)
A36: 130005007 | B36: Refresh | C36: RED | D36: 250 ml | E36: 6 | G36: 1200 | H36: 4.89 | I36: 1300050010011 | J36: =IF(F36="","",F36*H36)
A37: 130005008 | B37: Refresh | C37: VIOLET | D37: 250 ml | E37: 6 | G37: 1200 | H37: 4.89 | I37: 1300050010011 | J37: =IF(F37="","",F37*H37)
A38: 130005009 | B38: Refresh | C38: AMETHYST | D38: 250 ml | E38: 6 | G38: 1200 | H38: 4.89 | I38: 1300050010011 | J38: =IF(F38="","",F38*H38)
A39: 130005010 | B39: Refresh | C39: ACQUAMARINE | D39: 250 ml | E39: 6 | G39: 1200 | H39: 4.89 | I39: 1300050010011 | J39: =IF(F39="","",F39*H39)
A40: 130005011 | B40: Refresh | C40: PINK | D40: 250 ml | E40: 6 | G40: 1200 | H40: 4.89 | I40: 1300050010011 | J40: =IF(F40="","",F40*H40)
A41: 130005013 | B41: Refresh | C41: SAND | D41: 250 ml | E41: 6 | G41: 1200 | H41: 4.89 | I41: 1300050010011 | J41: =IF(F41="","",F41*H41)
A43: 130010000 | B43: Refoam | C43: Black 13 | D43: 200ml | E43: 12 | H43: 2.59 | I43: 1300100000016 | J43: =IF(F43="","",F43*H43)
A44: 130006000 | B44: Refoam | C44: Intese Grey 24 | D44: 200ml | E44: 12 | H44: 2.59 | I44: 1300060000019 | J44: =IF(F44="","",F44*H44)
A45: 130012000 | B45: Refoam | C45: Steel Grey 23 | D45: 200ml | E45: 12 | H45: 2.59 | I45: 1300120000010 | J45: =IF(F45="","",F45*H45)
A46: 130009000 | B46: Refoam | C46: Silver 22 | D46: 200ml | E46: 12 | H46: 2.59 | I46: 1300090000010 | J46: =IF(F46="","",F46*H46)
A47: 130011000 | B47: Refoam | C47: Dark Brown 14 | D47: 200ml | E47: 12 | H47: 2.59 | I47: 1300110000013 | J47: =IF(F47="","",F47*H47)
A48: 130007000 | B48: Refoam | C48: Chestnut 15 | D48: 200ml | E48: 12 | H48: 2.59 | I48: 1300070000016 | J48: =IF(F48="","",F48*H48)
A49: 130013000 | B49: Refoam | C49: Dark Blonde 16 | D49: 200ml | E49: 12 | H49: 2.59 | I49: 1300130000017 | J49: =IF(F49="","",F49*H49)
A50: 130008000 | B50: Refoam | C50: Natural Blonde 17 | D50: 200ml | E50: 12 | H50: 2.59 | I50: 1300080000013 | J50: =IF(F50="","",F50*H50)
...
